WARNING - 2021-08-08 10:14:27,199 - s3_upload.__main__ - main.main - MainThread - User terminate program! in /Users/rkrivov/PycharmProjects/s3_upload/main.py:91
WARNING - 2021-08-08 10:49:49,836 - s3_upload.__main__ - main.main - MainThread - User terminate program! in /Users/rkrivov/PycharmProjects/s3_upload/main.py:91
WARNING - 2021-08-08 10:51:21,893 - s3_upload.__main__ - main.main - MainThread - User terminate program! in /Users/rkrivov/PycharmProjects/s3_upload/main.py:91
WARNING - 2021-08-08 10:52:34,827 - s3_upload.__main__ - main.main - MainThread - User terminate program! in /Users/rkrivov/PycharmProjects/s3_upload/main.py:91
WARNING - 2021-08-08 10:53:12,464 - s3_upload.__main__ - main.main - MainThread - User terminate program! in /Users/rkrivov/PycharmProjects/s3_upload/main.py:91
WARNING - 2021-08-08 10:54:33,266 - s3_upload.__main__ - main.main - MainThread - User terminate program! in /Users/rkrivov/PycharmProjects/s3_upload/main.py:91
WARNING - 2021-08-08 10:56:09,212 - s3_upload.__main__ - main.main - MainThread - User terminate program! in /Users/rkrivov/PycharmProjects/s3_upload/main.py:91
WARNING - 2021-08-08 11:13:53,035 - s3_upload.__main__ - main.main - MainThread - User terminate program! in /Users/rkrivov/PycharmProjects/s3_upload/main.py:91
WARNING - 2021-08-08 11:15:18,572 - s3_upload.__main__ - main.main - MainThread - User terminate program! in /Users/rkrivov/PycharmProjects/s3_upload/main.py:91
WARNING - 2021-08-08 11:20:52,790 - s3_upload.__main__ - main.main - MainThread - User terminate program! in /Users/rkrivov/PycharmProjects/s3_upload/main.py:91
CRITICAL - 2021-08-08 11:26:34,965 - s3_upload.__main__ - main.main - MainThread - Exception ExecuteCommandException with message "Delete the snapshot...
Failed to delete snapshot: Not enough free space to merge the snapshots. Free some disk space on the physical hard disk and try again. (retcode is 255)." is not caught in /Users/rkrivov/PycharmProjects/s3_upload/main.py:101
Traceback (most recent call last):
  File "/Users/rkrivov/PycharmProjects/s3_upload/main.py", line 91, in main
    CommandDispatch.execute(args.operation,
  File "/Users/rkrivov/PycharmProjects/s3_upload/dispatchers/command_dispatch.py", line 46, in execute
    result = func(*args, **kwargs)
  File "/Users/rkrivov/PycharmProjects/s3_upload/main.py", line 35, in do_backup_vm
    S3ParallelsBackup.start(*args, **kwargs)
  File "/Users/rkrivov/PycharmProjects/s3_upload/s3/s3parallels/operation.py", line 509, in start
    o.execute(*args, **kwargs)
  File "/Users/rkrivov/PycharmProjects/s3_upload/s3/s3parallels/operation.py", line 499, in execute
    super(S3ParallelsOperation, self).execute(*args, **kwargs)
  File "/Users/rkrivov/PycharmProjects/s3_upload/s3/s3base/s3baseobject.py", line 525, in execute
    self.process()
  File "/Users/rkrivov/PycharmProjects/s3_upload/s3/s3parallels/operation.py", line 495, in process
    self._process(virtual_machine=virtual_machine)
  File "/Users/rkrivov/PycharmProjects/s3_upload/s3/s3parallels/operation.py", line 477, in _process
    self._process_with_virtual_machine(virtual_machine=virtual_machine)
  File "/Users/rkrivov/PycharmProjects/s3_upload/s3/s3parallels/backup.py", line 64, in _process_with_virtual_machine
    self._update_snapshots(virtual_machine_id=virtual_machine_id)
  File "/Users/rkrivov/PycharmProjects/s3_upload/s3/s3parallels/backup.py", line 76, in _update_snapshots
    self.parallels.delete_snapshot(virtual_machine_id=virtual_machine_id,
  File "/Users/rkrivov/PycharmProjects/s3_upload/s3/s3parallels/parallels.py", line 159, in delete_snapshot
    self._execute_parallels_command(tuple(delete_command),
  File "/Users/rkrivov/PycharmProjects/s3_upload/s3/s3parallels/parallels.py", line 80, in _execute_parallels_command
    result = self._execute(self._parallels_control_command, command_string)
  File "/Users/rkrivov/PycharmProjects/s3_upload/s3/s3parallels/parallels.py", line 395, in _execute
    output = run_command(*args, **kwargs)
  File "/Users/rkrivov/PycharmProjects/s3_upload/utils/functions.py", line 205, in run_command
    raise ExecuteCommandException(error_message) from None
utils.exceptions.ExecuteCommandException: Delete the snapshot...
Failed to delete snapshot: Not enough free space to merge the snapshots. Free some disk space on the physical hard disk and try again. (retcode is 255).
Stack (most recent call last):
  File "/Users/rkrivov/PycharmProjects/s3_upload/main.py", line 115, in <module>
    main()
  File "/Users/rkrivov/PycharmProjects/s3_upload/main.py", line 101, in main
    logger.critical(
CRITICAL - 2021-08-08 11:27:24,879 - s3_upload.__main__ - main.main - MainThread - Exception ExecuteCommandException with message "Delete the snapshot...
Failed to delete snapshot: Not enough free space to merge the snapshots. Free some disk space on the physical hard disk and try again. (retcode is 255)." is not caught in /Users/rkrivov/PycharmProjects/s3_upload/main.py:101
Traceback (most recent call last):
  File "/Users/rkrivov/PycharmProjects/s3_upload/main.py", line 91, in main
    CommandDispatch.execute(args.operation,
  File "/Users/rkrivov/PycharmProjects/s3_upload/dispatchers/command_dispatch.py", line 46, in execute
    result = func(*args, **kwargs)
  File "/Users/rkrivov/PycharmProjects/s3_upload/main.py", line 35, in do_backup_vm
    S3ParallelsBackup.start(*args, **kwargs)
  File "/Users/rkrivov/PycharmProjects/s3_upload/s3/s3parallels/operation.py", line 509, in start
    o.execute(*args, **kwargs)
  File "/Users/rkrivov/PycharmProjects/s3_upload/s3/s3parallels/operation.py", line 499, in execute
    super(S3ParallelsOperation, self).execute(*args, **kwargs)
  File "/Users/rkrivov/PycharmProjects/s3_upload/s3/s3base/s3baseobject.py", line 525, in execute
    self.process()
  File "/Users/rkrivov/PycharmProjects/s3_upload/s3/s3parallels/operation.py", line 495, in process
    self._process(virtual_machine=virtual_machine)
  File "/Users/rkrivov/PycharmProjects/s3_upload/s3/s3parallels/operation.py", line 477, in _process
    self._process_with_virtual_machine(virtual_machine=virtual_machine)
  File "/Users/rkrivov/PycharmProjects/s3_upload/s3/s3parallels/backup.py", line 64, in _process_with_virtual_machine
    self._update_snapshots(virtual_machine_id=virtual_machine_id)
  File "/Users/rkrivov/PycharmProjects/s3_upload/s3/s3parallels/backup.py", line 76, in _update_snapshots
    self.parallels.delete_snapshot(virtual_machine_id=virtual_machine_id,
  File "/Users/rkrivov/PycharmProjects/s3_upload/s3/s3parallels/parallels.py", line 159, in delete_snapshot
    self._execute_parallels_command(tuple(delete_command),
  File "/Users/rkrivov/PycharmProjects/s3_upload/s3/s3parallels/parallels.py", line 80, in _execute_parallels_command
    result = self._execute(self._parallels_control_command, command_string)
  File "/Users/rkrivov/PycharmProjects/s3_upload/s3/s3parallels/parallels.py", line 395, in _execute
    output = run_command(*args, **kwargs)
  File "/Users/rkrivov/PycharmProjects/s3_upload/utils/functions.py", line 205, in run_command
    raise ExecuteCommandException(error_message) from None
utils.exceptions.ExecuteCommandException: Delete the snapshot...
Failed to delete snapshot: Not enough free space to merge the snapshots. Free some disk space on the physical hard disk and try again. (retcode is 255).
WARNING - 2021-08-08 16:56:35,886 - s3_upload.__main__ - main.main - MainThread - User terminate program! in /Users/rkrivov/PycharmProjects/s3_upload/main.py:99
WARNING - 2021-08-08 16:59:20,330 - s3_upload.__main__ - main.main - MainThread - User terminate program! in /Users/rkrivov/PycharmProjects/s3_upload/main.py:91
WARNING - 2021-08-08 17:06:57,264 - s3_upload.__main__ - main.main - MainThread - User terminate program! in /Users/rkrivov/PycharmProjects/s3_upload/main.py:91
CRITICAL - 2021-08-08 17:06:59,442 - s3_upload.__main__ - main.main - MainThread - Exception SyntaxError with message "invalid syntax (backup.py, line 82)" is not caught in /Users/rkrivov/PycharmProjects/s3_upload/main.py:101
Traceback (most recent call last):
  File "/Users/rkrivov/PycharmProjects/s3_upload/main.py", line 91, in main
    CommandDispatch.execute(args.operation,
  File "/Users/rkrivov/PycharmProjects/s3_upload/dispatchers/command_dispatch.py", line 46, in execute
    result = func(*args, **kwargs)
  File "/Users/rkrivov/PycharmProjects/s3_upload/main.py", line 33, in do_backup_vm
    from s3.s3parallels.backup import S3ParallelsBackup
  File "/Users/rkrivov/PycharmProjects/s3_upload/s3/s3parallels/backup.py", line 82
    if len(snapshot_list) < VM_SNAPSHOT_COUNT:
                                             ^
SyntaxError: invalid syntax
CRITICAL - 2021-08-08 17:11:30,793 - s3_upload.__main__ - main.main - MainThread - Exception NameError with message "name 'locale_path' is not defined" is not caught in /Users/rkrivov/PycharmProjects/s3_upload/main.py:101
Traceback (most recent call last):
  File "/Users/rkrivov/PycharmProjects/s3_upload/main.py", line 91, in main
    CommandDispatch.execute(args.operation,
  File "/Users/rkrivov/PycharmProjects/s3_upload/dispatchers/command_dispatch.py", line 46, in execute
    result = func(*args, **kwargs)
  File "/Users/rkrivov/PycharmProjects/s3_upload/main.py", line 35, in do_backup_vm
    S3ParallelsBackup.start(*args, **kwargs)
  File "/Users/rkrivov/PycharmProjects/s3_upload/s3/s3parallels/operation.py", line 509, in start
    o.execute(*args, **kwargs)
  File "/Users/rkrivov/PycharmProjects/s3_upload/s3/s3parallels/operation.py", line 499, in execute
    super(S3ParallelsOperation, self).execute(*args, **kwargs)
  File "/Users/rkrivov/PycharmProjects/s3_upload/s3/s3base/s3baseobject.py", line 525, in execute
    self.process()
  File "/Users/rkrivov/PycharmProjects/s3_upload/s3/s3parallels/operation.py", line 495, in process
    self._process(virtual_machine=virtual_machine)
  File "/Users/rkrivov/PycharmProjects/s3_upload/s3/s3parallels/operation.py", line 477, in _process
    self._process_with_virtual_machine(virtual_machine=virtual_machine)
  File "/Users/rkrivov/PycharmProjects/s3_upload/s3/s3parallels/backup.py", line 66, in _process_with_virtual_machine
    super(S3ParallelsBackup, self)._process_with_virtual_machine(virtual_machine=virtual_machine)
  File "/Users/rkrivov/PycharmProjects/s3_upload/s3/s3parallels/operation.py", line 430, in _process_with_virtual_machine
    files = self._fetch_local_files_list(local_path=locale_path)
NameError: name 'locale_path' is not defined
WARNING - 2021-08-08 17:14:41,415 - s3_upload.__main__ - main.main - MainThread - User terminate program! in /Users/rkrivov/PycharmProjects/s3_upload/main.py:91
