ERROR - 2021-08-15 15:35:51,199 - s3_upload.__main__ - main.main - MainThread - upload_file() missing 2 required positional arguments: 'local_file_path' and 'remote_file_path' in /Users/rkrivov/PycharmProjects/s3_upload/main.py:117
Traceback (most recent call last):
  File "/Users/rkrivov/PycharmProjects/s3_upload/main.py", line 113, in main
    CommandDispatch.execute(args.operation, **kwargs)
  File "/Users/rkrivov/PycharmProjects/s3_upload/dispatchers/command_dispatch.py", line 46, in execute
    result = func(*args, **kwargs)
  File "/Users/rkrivov/PycharmProjects/s3_upload/main.py", line 34, in do_backup_vm
    S3ParallelsBackup.start(*args, **kwargs)
  File "/Users/rkrivov/PycharmProjects/s3_upload/s3/s3parallels/operation.py", line 849, in start
    o.execute(*args, **kwargs)
  File "/Users/rkrivov/PycharmProjects/s3_upload/s3/s3base/s3baseobject.py", line 558, in execute
    self.process()
  File "/Users/rkrivov/PycharmProjects/s3_upload/s3/s3parallels/operation.py", line 836, in process
    self._process(virtual_machine=virtual_machine)
  File "/Users/rkrivov/PycharmProjects/s3_upload/s3/s3parallels/operation.py", line 727, in _process
    self._process_with_virtual_machine(virtual_machine=virtual_machine)
  File "/Users/rkrivov/PycharmProjects/s3_upload/s3/s3parallels/backup.py", line 188, in _process_with_virtual_machine
    super(S3ParallelsBackup, self)._process_with_virtual_machine(virtual_machine=virtual_machine)
  File "/Users/rkrivov/PycharmProjects/s3_upload/s3/s3parallels/operation.py", line 687, in _process_with_virtual_machine
    self.operation(files, virtual_machine=virtual_machine)
  File "/Users/rkrivov/PycharmProjects/s3_upload/s3/s3parallels/backup.py", line 178, in operation
    self._do_file_operation(operation_id=operation_id,
  File "/Users/rkrivov/PycharmProjects/s3_upload/s3/s3parallels/backup.py", line 165, in _do_file_operation
    S3ParallelsBackupDispatch.execute(operation_id, self,
  File "/Users/rkrivov/PycharmProjects/s3_upload/s3/s3parallels/backup.py", line 53, in execute
    result = func(wself, *args, **kwargs)
  File "/Users/rkrivov/PycharmProjects/s3_upload/s3/s3parallels/backup.py", line 128, in _do_update_file
    self.storage.upload_file(local_file_path=local_file_name,
  File "/Users/rkrivov/PycharmProjects/s3_upload/s3/s3functions.py", line 19, in wrapper_func
    result = fn(*args, **kwargs)
TypeError: upload_file() missing 2 required positional arguments: 'local_file_path' and 'remote_file_path'
WARNING - 2021-08-15 17:58:48,130 - s3_upload.__main__ - main.main - MainThread - User terminate program! in /Users/rkrivov/PycharmProjects/s3_upload/main.py:113
WARNING - 2021-08-15 18:45:19,487 - s3_upload.__main__ - main.main - MainThread - User terminate program! in /Users/rkrivov/PycharmProjects/s3_upload/main.py:115
WARNING - 2021-08-15 18:45:52,481 - s3_upload.__main__ - main.main - MainThread - User terminate program! in /Users/rkrivov/PycharmProjects/s3_upload/main.py:115
